2025-09-16 17:13:54,837 - INFO - uvicorn.error - Will watch for changes in these directories: ['c:\\s2\\RailSathiBE']
2025-09-16 17:13:54,837 - INFO - uvicorn.error - Uvicorn running on http://127.0.0.1:8000 (Press CTRL+C to quit)
2025-09-16 17:13:54,837 - INFO - uvicorn.error - Started reloader process [5304] using StatReload
2025-09-16 17:13:56,258 - INFO - uvicorn.error - Started server process [14096]
2025-09-16 17:13:56,258 - INFO - uvicorn.error - Waiting for application startup.
2025-09-16 17:13:56,258 - INFO - uvicorn.error - Application startup complete.
2025-09-16 17:15:46,723 - INFO - uvicorn.access - 127.0.0.1:62992 - "GET /rs_microservice/docs HTTP/1.1" 200
2025-09-16 17:15:47,000 - INFO - uvicorn.access - 127.0.0.1:62992 - "GET /rs_microservice/openapi.json HTTP/1.1" 200
2025-09-16 17:16:01,350 - ERROR - main - Error getting complaint 544: 1 validation error for RailSathiComplainResponse
data.customer_care
  Field required [type=missing, input_value={'complain_id': 544, 'pnr...mplain_media_files': []}, input_type=dict]
    For further information visit https://errors.pydantic.dev/2.11/v/missing
2025-09-16 17:16:01,366 - INFO - uvicorn.access - 127.0.0.1:65411 - "GET /rs_microservice/complaint/get/544 HTTP/1.1" 500
2025-09-16 17:18:20,386 - INFO - services - Starting passenger complaint email thread for updated complaint 544
2025-09-16 17:18:20,388 - INFO - services - Email thread started for updated complaint 544
2025-09-16 17:18:20,388 - INFO - services - Passenger complaint email thread started with name EmailThread-Update-544
2025-09-16 17:18:20,394 - INFO - services - Starting file upload for complaint 544, file: Screenshot 2025-08-14 184626.png
2025-09-16 17:18:20,396 - INFO - services - File content size: 531409 bytes
2025-09-16 17:18:20,396 - INFO - services - Processing file: Screenshot 2025-08-14 184626.png, content_type: image/png
2025-09-16 17:18:20,397 - INFO - services - Uploading image file: Screenshot 2025-08-14 184626.png
2025-09-16 17:18:20,432 - INFO - services - Sending passenger complaint email for updated complaint 544 to war room users
2025-09-16 17:18:20,948 - INFO - root - No FCM tokens available for complaint 544
2025-09-16 17:18:20,955 - INFO - root - No users found for depot  and train 12256 in complaint 544
2025-09-16 17:18:20,956 - INFO - services - Passenger complaint email sent successfully for updated complaint 544
2025-09-16 17:18:32,356 - ERROR - services - Error in upload_file_thread for file Screenshot 2025-08-14 184626.png: Your default credentials were not found. To set up Application Default Credentials, see https://cloud.google.com/docs/authentication/external/set-up-adc for more information.
2025-09-16 17:18:32,360 - ERROR - services - Full traceback: Traceback (most recent call last):
  File "c:\s2\RailSathiBE\services.py", line 162, in upload_file_thread
    uploaded_url = process_media_file_upload(file_content, ext, complain_id, media_type)
  File "c:\s2\RailSathiBE\services.py", line 123, in process_media_file_upload
    raise e
  File "c:\s2\RailSathiBE\services.py", line 61, in process_media_file_upload
    client = get_gcs_client()
  File "c:\s2\RailSathiBE\services.py", line 34, in get_gcs_client
    client = storage.Client(project=PROJECT_ID)
  File "c:\s2\Sanchalak_BE\venv\lib\site-packages\google\cloud\storage\client.py", line 247, in __init__
    super(Client, self).__init__(
  File "c:\s2\Sanchalak_BE\venv\lib\site-packages\google\cloud\client\__init__.py", line 339, in __init__
    Client.__init__(
  File "c:\s2\Sanchalak_BE\venv\lib\site-packages\google\cloud\client\__init__.py", line 196, in __init__
    credentials, _ = google.auth.default(scopes=scopes)
  File "c:\s2\Sanchalak_BE\venv\lib\site-packages\google\auth\_default.py", line 685, in default
    raise exceptions.DefaultCredentialsError(_CLOUD_SDK_MISSING_CREDENTIALS)
google.auth.exceptions.DefaultCredentialsError: Your default credentials were not found. To set up Application Default Credentials, see https://cloud.google.com/docs/authentication/external/set-up-adc for more information.

2025-09-16 17:18:33,398 - INFO - uvicorn.access - 127.0.0.1:60448 - "PUT /rs_microservice/complaint/update/544 HTTP/1.1" 500
2025-09-16 17:18:33,399 - ERROR - uvicorn.error - Exception in ASGI application
Traceback (most recent call last):
  File "c:\s2\Sanchalak_BE\venv\lib\site-packages\uvicorn\protocols\http\h11_impl.py", line 403, in run_asgi
    result = await app(  # type: ignore[func-returns-value]
  File "c:\s2\Sanchalak_BE\venv\lib\site-packages\uvicorn\middleware\proxy_headers.py", line 60, in __call__
    return await self.app(scope, receive, send)
  File "c:\s2\Sanchalak_BE\venv\lib\site-packages\fastapi\applications.py", line 1054, in __call__
    await super().__call__(scope, receive, send)
  File "c:\s2\Sanchalak_BE\venv\lib\site-packages\starlette\applications.py", line 113, in __call__
    await self.middleware_stack(scope, receive, send)
  File "c:\s2\Sanchalak_BE\venv\lib\site-packages\starlette\middleware\errors.py", line 186, in __call__
    raise exc
  File "c:\s2\Sanchalak_BE\venv\lib\site-packages\starlette\middleware\errors.py", line 164, in __call__
    await self.app(scope, receive, _send)
  File "c:\s2\Sanchalak_BE\venv\lib\site-packages\starlette\middleware\cors.py", line 93, in __call__
    await self.simple_response(scope, receive, send, request_headers=headers)
  File "c:\s2\Sanchalak_BE\venv\lib\site-packages\starlette\middleware\cors.py", line 144, in simple_response
    await self.app(scope, receive, send)
  File "c:\s2\Sanchalak_BE\venv\lib\site-packages\starlette\middleware\exceptions.py", line 63, in __call__
    await wrap_app_handling_exceptions(self.app, conn)(scope, receive, send)
  File "c:\s2\Sanchalak_BE\venv\lib\site-packages\starlette\_exception_handler.py", line 53, in wrapped_app
    raise exc
  File "c:\s2\Sanchalak_BE\venv\lib\site-packages\starlette\_exception_handler.py", line 42, in wrapped_app
    await app(scope, receive, sender)
  File "c:\s2\Sanchalak_BE\venv\lib\site-packages\starlette\routing.py", line 716, in __call__
    await self.middleware_stack(scope, receive, send)
  File "c:\s2\Sanchalak_BE\venv\lib\site-packages\starlette\routing.py", line 736, in app
    await route.handle(scope, receive, send)
  File "c:\s2\Sanchalak_BE\venv\lib\site-packages\starlette\routing.py", line 290, in handle
    await self.app(scope, receive, send)
  File "c:\s2\Sanchalak_BE\venv\lib\site-packages\starlette\routing.py", line 78, in app
    await wrap_app_handling_exceptions(app, request)(scope, receive, send)
  File "c:\s2\Sanchalak_BE\venv\lib\site-packages\starlette\_exception_handler.py", line 53, in wrapped_app
    raise exc
  File "c:\s2\Sanchalak_BE\venv\lib\site-packages\starlette\_exception_handler.py", line 42, in wrapped_app
    await app(scope, receive, sender)
  File "c:\s2\Sanchalak_BE\venv\lib\site-packages\starlette\routing.py", line 75, in app
    response = await f(request)
  File "c:\s2\Sanchalak_BE\venv\lib\site-packages\fastapi\routing.py", line 328, in app
    content = await serialize_response(
  File "c:\s2\Sanchalak_BE\venv\lib\site-packages\fastapi\routing.py", line 177, in serialize_response
    raise ResponseValidationError(
fastapi.exceptions.ResponseValidationError: 1 validation errors:
  {'type': 'missing', 'loc': ('response', 'data', 'customer_care'), 'msg': 'Field required', 'input': {'complain_id': 544, 'pnr_number': '9999999999', 'is_pnr_validated': 'not-attempted', 'name': 'asad', 'mobile_number': '8517078080', 'complain_type': 'cleaning', 'complain_description': 'dirty coach', 'complain_date': '2025-08-22', 'complain_status': 'pending', 'coach': 'S1', 'berth_no': 5, 'created_at': '2025-09-15T11:05:08.150300+05:30', 'updated_at': '2025-09-16T17:18:20.332820+05:30', 'created_by': 'asad', 'train_id': 123, 'updated_by': 'asad', 'train_name': None, 'train_number': '12256', 'submission_status': 'submitted', 'train_no': None, 'train_depot': None, 'rail_sathi_complain_media_files': []}}

